<?xml version="1.0" ?>
<!-- =================================================================================== -->
<!-- |    This document was autogenerated by xacro from agro.urdf.xacro                | -->
<!-- |    EDITING THIS FILE BY HAND IS NOT RECOMMENDED                                 | -->
<!-- =================================================================================== -->
<robot name="robot_name">
  <!-- ************************ -->
  <!--  variables -->
  <!-- ************************ -->
  <!-- Base footprint-->
  <link name="base_footprint">
    </link>
  <link name="base_link">
    <visual>
      <origin rpy="0.0 0.0 0.0" xyz="0.0 0.0 0.0"/>
      <geometry>
        <!--box size="0.5 0.316 0.16"/-->
        <mesh filename="file:///home/christopher/christopher/CHRISTOPHER/ros2_ws/install/agro_description/share/agro_description/mesh/base.stl" scale="0.001 0.001 0.001"/>
      </geometry>
      <material name="wood">
        <color rgba="0.76 0.60 0.42 1.0"/>
        <!-- Color madera -->
      </material>
    </visual>
    <inertial>
      <origin rpy="0.0 0.0 0.0" xyz="0.0 0.0 0.0"/>
      <mass value="0.2"/>
      <inertia ixx="0.0021333333333333334" ixy="0.0" ixz="0.0" iyy="0.004593333333333334" iyz="0.0" izz="0.005873333333333333"/>
    </inertial>
    <collision>
      <origin rpy="0.0 0.0 0.0" xyz="0.0 0.0 0.08"/>
      <geometry>
        <box size="0.5 0.32 0.16"/>
        <!--0.5 0.316 0.16-->
      </geometry>
    </collision>
  </link>
  <joint name="base_footprint_joint" type="fixed">
    <origin rpy="0.0 0.0 0.0" xyz="0.0 0.0 0.2"/>
    <parent link="base_footprint"/>
    <child link="base_link"/>
  </joint>
  <link name="chassis_link">
    <visual>
      <origin rpy="0.0 0.0 0.0" xyz="0.0 0.0 0.0"/>
      <geometry>
        <!--box size="0.5 0.316 0.16"/-->
        <mesh filename="file:///home/christopher/christopher/CHRISTOPHER/ros2_ws/install/agro_description/share/agro_description/mesh/chassis.stl" scale="0.001 0.001 0.001"/>
      </geometry>
      <material name="steel">
        <color rgba="0.70 0.70 0.70 1.0"/>
        <!-- Color acero -->
      </material>
    </visual>
    <inertial>
      <origin rpy="0.0 0.0 0.0" xyz="0.0 0.0 0.0"/>
      <mass value="2.0"/>
      <inertia ixx="0.03651202666666666" ixy="0.0" ixz="0.0" iyy="0.039512026666666665" iyz="0.0" izz="0.06753333333333333"/>
    </inertial>
    <collision>
      <origin rpy="0.0 0.0 0.0" xyz="0.0 0.0 -0.0798"/>
      <geometry>
        <box size="0.46 0.44 0.1596"/>
      </geometry>
    </collision>
  </link>
  <joint name="base_chassis_joint" type="fixed">
    <origin rpy="0.0 0.0 0.0" xyz="0.0 0.0 0.0"/>
    <parent link="base_link"/>
    <child link="chassis_link"/>
  </joint>
  <link name="soporte_link">
    <visual>
      <origin rpy="0.0 0.0 0.0" xyz="0.0 0.0 0.0"/>
      <geometry>
        <mesh filename="file:///home/christopher/christopher/CHRISTOPHER/ros2_ws/install/agro_description/share/agro_description/mesh/soporte.stl" scale="0.001 0.001 0.001"/>
      </geometry>
      <material name="steel">
        <color rgba="0.70 0.70 0.70 1.0"/>
      </material>
    </visual>
    <inertial>
      <origin rpy="0.0 0.0 0.0" xyz="0.0 0.0 0.30"/>
      <mass value="0.1"/>
      <inertia ixx="0.003003333333333333" ixy="0.0" ixz="0.0" iyy="0.003003333333333333" iyz="0.0" izz="6.666666666666667e-06"/>
    </inertial>
    <collision>
      <origin rpy="0.0 0.0 0.0" xyz="0.0 0.0 0.30"/>
      <geometry>
        <box size="0.02 0.02 0.6"/>
      </geometry>
    </collision>
  </link>
  <joint name="base_soporte_joint" type="fixed">
    <origin rpy="0.0 0.0 0.0" xyz="0.21 0.0 0.16"/>
    <parent link="base_link"/>
    <child link="soporte_link"/>
  </joint>
  <!-- Box -->
  <!--xacro:box/-->
  <link name="head_link">
    <visual>
      <origin rpy="0.0 0.0 0.0" xyz="0.0 0.0 0.0"/>
      <geometry>
        <mesh filename="file:///home/christopher/christopher/CHRISTOPHER/ros2_ws/install/agro_description/share/agro_description/mesh/base_camara.stl" scale="0.001 0.001 0.001"/>
      </geometry>
      <material name="wood">
        <color rgba="0.76 0.60 0.42 1.0"/>
        <!-- Color madera -->
      </material>
    </visual>
    <inertial>
      <origin rpy="0.0 0.0 0.0" xyz="0.01 0.0 0.0015"/>
      <mass value="0.05"/>
      <inertia ixx="9.37875e-05" ixy="0.0" ixz="0.0" iyy="0.00010670416666666666" iyz="0.0" izz="0.00020041666666666667"/>
    </inertial>
    <collision>
      <origin rpy="0.0 0.0 0.0" xyz="0.01 0.0 0.0015"/>
      <geometry>
        <box size="0.16 0.15 0.003"/>
      </geometry>
    </collision>
  </link>
  <joint name="base_head_joint" type="fixed">
    <origin rpy="0.0 0.0 0.0" xyz="0.21 0.0 0.76"/>
    <parent link="base_link"/>
    <child link="head_link"/>
  </joint>
  <link name="front_left_wheel">
    <visual name="">
      <origin rpy="1.57 0.0 0.0" xyz="0.0 0.0 0.0"/>
      <geometry>
        <mesh filename="file:///home/christopher/christopher/CHRISTOPHER/ros2_ws/install/agro_description/share/agro_description/mesh/rueda.stl" scale="0.001 0.001 0.001"/>
      </geometry>
      <material name="material_wheel">
        <color rgba="0.0 0.0 0.0 1.0"/>
      </material>
    </visual>
    <inertial>
      <origin rpy="1.57  0 0" xyz="0.0 0 0"/>
      <mass value="0.4"/>
      <inertia ixx="0.00048727600000000003" ixy="0.0" ixz="0.0" iyy="0.00048727600000000003" iyz="0.0" izz="0.000722402"/>
    </inertial>
    <collision>
      <origin rpy="1.57  0.0 0.0" xyz="0.0 0.0 0.0"/>
      <geometry>
        <cylinder length="0.0615" radius="0.0601"/>
      </geometry>
    </collision>
  </link>
  <link name="front_right_wheel">
    <visual name="">
      <origin rpy="1.57 0.0 0.0" xyz="0.0 0.0 0.0"/>
      <geometry>
        <mesh filename="file:///home/christopher/christopher/CHRISTOPHER/ros2_ws/install/agro_description/share/agro_description/mesh/rueda.stl" scale="0.001 0.001 0.001"/>
      </geometry>
      <material name="material_wheel">
        <color rgba="0.0 0.0 0.0 1.0"/>
      </material>
    </visual>
    <inertial>
      <origin rpy="1.57  0 0" xyz="0.0 0 0"/>
      <mass value="0.4"/>
      <inertia ixx="0.00048727600000000003" ixy="0.0" ixz="0.0" iyy="0.00048727600000000003" iyz="0.0" izz="0.000722402"/>
    </inertial>
    <collision>
      <origin rpy="1.57  0.0 0.0" xyz="0.0 0.0 0.0"/>
      <geometry>
        <cylinder length="0.0615" radius="0.0601"/>
      </geometry>
    </collision>
  </link>
  <link name="near_left_wheel">
    <visual name="">
      <origin rpy="1.57 0.0 0.0" xyz="0.0 0.0 0.0"/>
      <geometry>
        <mesh filename="file:///home/christopher/christopher/CHRISTOPHER/ros2_ws/install/agro_description/share/agro_description/mesh/rueda.stl" scale="0.001 0.001 0.001"/>
      </geometry>
      <material name="material_wheel">
        <color rgba="0.0 0.0 0.0 1.0"/>
      </material>
    </visual>
    <inertial>
      <origin rpy="1.57  0 0" xyz="0.0 0 0"/>
      <mass value="0.4"/>
      <inertia ixx="0.00048727600000000003" ixy="0.0" ixz="0.0" iyy="0.00048727600000000003" iyz="0.0" izz="0.000722402"/>
    </inertial>
    <collision>
      <origin rpy="1.57  0.0 0.0" xyz="0.0 0.0 0.0"/>
      <geometry>
        <cylinder length="0.0615" radius="0.0601"/>
      </geometry>
    </collision>
  </link>
  <link name="near_right_wheel">
    <visual name="">
      <origin rpy="1.57 0.0 0.0" xyz="0.0 0.0 0.0"/>
      <geometry>
        <mesh filename="file:///home/christopher/christopher/CHRISTOPHER/ros2_ws/install/agro_description/share/agro_description/mesh/rueda.stl" scale="0.001 0.001 0.001"/>
      </geometry>
      <material name="material_wheel">
        <color rgba="0.0 0.0 0.0 1.0"/>
      </material>
    </visual>
    <inertial>
      <origin rpy="1.57  0 0" xyz="0.0 0 0"/>
      <mass value="0.4"/>
      <inertia ixx="0.00048727600000000003" ixy="0.0" ixz="0.0" iyy="0.00048727600000000003" iyz="0.0" izz="0.000722402"/>
    </inertial>
    <collision>
      <origin rpy="1.57  0.0 0.0" xyz="0.0 0.0 0.0"/>
      <geometry>
        <cylinder length="0.0615" radius="0.0601"/>
      </geometry>
    </collision>
  </link>
  <joint name="front_left_joint" type="continuous">
    <origin rpy="0.0 0.0 0.0" xyz="0.21 0.224 -0.1376"/>
    <parent link="base_link"/>
    <child link="front_left_wheel"/>
    <axis xyz="0.0 1.0 0.0"/>
    <limit effort="1.5" velocity="30.0"/>
    <dynamics damping="0.001" friction="0.001"/>
  </joint>
  <joint name="front_right_joint" type="continuous">
    <origin rpy="0.0 0.0 0.0" xyz="0.21 -0.224 -0.1376"/>
    <parent link="base_link"/>
    <child link="front_right_wheel"/>
    <axis xyz="0.0 1.0 0.0"/>
    <limit effort="1.5" velocity="30.0"/>
    <dynamics damping="0.001" friction="0.001"/>
  </joint>
  <joint name="near_left_joint" type="continuous">
    <origin rpy="0.0 0.0 0.0" xyz="-0.21 0.224 -0.1376"/>
    <parent link="base_link"/>
    <child link="near_left_wheel"/>
    <axis xyz="0.0 1.0 0.0"/>
    <limit effort="1.5" velocity="30.0"/>
    <dynamics damping="0.001" friction="0.001"/>
  </joint>
  <joint name="near_right_joint" type="continuous">
    <origin rpy="0.0 0.0 0.0" xyz="-0.219 -0.224 -0.1376"/>
    <parent link="base_link"/>
    <child link="near_right_wheel"/>
    <axis xyz="0.0 1.0 0.0"/>
    <limit effort="1.5" velocity="30.0"/>
    <dynamics damping="0.001" friction="0.001"/>
  </joint>
  <link name="camera_link">
    <visual>
      <origin rpy="0.0 0.0 0.0" xyz="0.0 0.0 0.0"/>
      <geometry>
        <box size="0.02 0.02 0.02"/>
      </geometry>
      <material name="red">
        <color rgba="0.8 0.0 0.0 1.0"/>
        <!-- Color madera -->
      </material>
    </visual>
    <inertial>
      <origin rpy="0.0 0.0 0.0" xyz="0.01 0.0 0.0015"/>
      <mass value="0.001"/>
      <inertia ixx="6.666666666666667e-08" ixy="0.0" ixz="0.0" iyy="6.666666666666667e-08" iyz="0.0" izz="6.666666666666667e-08"/>
    </inertial>
    <collision>
      <origin rpy="0.0 0.0 0.0" xyz="0.01 0.0 0.0015"/>
      <geometry>
        <box size="0.02 0.02 0.02"/>
      </geometry>
    </collision>
  </link>
  <joint name="base_camera_joint" type="fixed">
    <origin rpy="0.0 0.0 1.57079632679" xyz="0.18 0.08 0.40"/>
    <parent link="base_link"/>
    <child link="camera_link"/>
  </joint>
  <link name="imu_link">
    <visual>
      <origin rpy="0.0 0.0 0.0" xyz="0.0 0.0 0.0"/>
      <geometry>
        <box size="0.02 0.02 0.02"/>
      </geometry>
      <material name="black">
        <color rgba="0.0 0.0 0.0 1.0"/>
      </material>
    </visual>
    <inertial>
      <origin rpy="0.0 0.0 0.0" xyz="0.01 0.0 0.0015"/>
      <mass value="0.001"/>
      <inertia ixx="6.666666666666667e-08" ixy="0.0" ixz="0.0" iyy="6.666666666666667e-08" iyz="0.0" izz="6.666666666666667e-08"/>
    </inertial>
    <collision>
      <origin rpy="0.0 0.0 0.0" xyz="0.01 0.0 0.0015"/>
      <geometry>
        <box size="0.02 0.02 0.02"/>
      </geometry>
    </collision>
  </link>
  <joint name="base_imu_joint" type="fixed">
    <origin rpy="0.0 0.0 0.0" xyz="0.18 0.0 0.015"/>
    <parent link="base_link"/>
    <child link="imu_link"/>
  </joint>
  <link name="gps_link">
    <visual>
      <origin rpy="0.0 0.0 0.0" xyz="0.0 0.0 0.0"/>
      <geometry>
        <box size="0.02 0.02 0.02"/>
      </geometry>
      <material name="blue">
        <color rgba="0.0 0.0 0.8 1.0"/>
        <!-- Color madera -->
      </material>
    </visual>
    <inertial>
      <origin rpy="0.0 0.0 0.0" xyz="0.01 0.0 0.0015"/>
      <mass value="0.001"/>
      <inertia ixx="6.666666666666667e-08" ixy="0.0" ixz="0.0" iyy="6.666666666666667e-08" iyz="0.0" izz="6.666666666666667e-08"/>
    </inertial>
    <collision>
      <origin rpy="0.0 0.0 0.0" xyz="0.01 0.0 0.0015"/>
      <geometry>
        <box size="0.02 0.02 0.02"/>
      </geometry>
    </collision>
  </link>
  <joint name="base_gps_joint" type="fixed">
    <origin rpy="0.0 0.0 0.0" xyz="0.21 0.0 0.77"/>
    <parent link="base_link"/>
    <child link="gps_link"/>
  </joint>
  <link name="laser_link">
    <visual>
      <origin rpy="0.0 0.0 0.0" xyz="0.0 0.0 0.0"/>
      <geometry>
        <box size="0.05 0.05 0.05"/>
      </geometry>
      <material name="black">
        <color rgba="0.0 0.0 0.0 1.0"/>
        <!-- Color madera -->
      </material>
    </visual>
    <inertial>
      <origin rpy="0.0 0.0 0.0" xyz="0.01 0.0 0.0015"/>
      <mass value="0.001"/>
      <inertia ixx="4.166666666666667e-07" ixy="0.0" ixz="0.0" iyy="4.166666666666667e-07" iyz="0.0" izz="4.166666666666667e-07"/>
    </inertial>
    <collision>
      <origin rpy="0.0 0.0 0.0" xyz="0.01 0.0 0.0015"/>
      <geometry>
        <box size="0.05 0.05 0.05"/>
      </geometry>
    </collision>
  </link>
  <joint name="base_lidar_joint" type="fixed">
    <origin rpy="0.0 0.0 0.0" xyz="0.21 0.04 0.185"/>
    <parent link="base_link"/>
    <child link="laser_link"/>
  </joint>
  <ros2_control name="wheels" type="system">
    <hardware>
      <plugin>agro_hardware_interfaces/AgroSystem</plugin>
      <param name="connection_timeout_ms">120000</param>
      <param name="connection_check_period_ms">500</param>
      <!-- order of velocity commands to be published in motors_cmd Float32MultiArray msg -->
      <param name="velocity_command_joint_order">
                    front_left_joint,
                    front_right_joint,
                    near_left_joint,
                    near_right_joint,
                </param>
    </hardware>
    <joint name="front_left_joint">
      <command_interface name="velocity"/>
      <state_interface name="position"/>
      <state_interface name="velocity"/>
    </joint>
    <joint name="near_left_joint">
      <command_interface name="velocity"/>
      <state_interface name="position"/>
      <state_interface name="velocity"/>
    </joint>
    <joint name="front_right_joint">
      <command_interface name="velocity"/>
      <state_interface name="position"/>
      <state_interface name="velocity"/>
    </joint>
    <joint name="near_right_joint">
      <command_interface name="velocity"/>
      <state_interface name="position"/>
      <state_interface name="velocity"/>
    </joint>
  </ros2_control>
  <!--xacro:wheels_friction side="front_left"/>
    <xacro:wheels_friction side="front_right"/>
    <xacro:wheels_friction side="near_left"/>
    <xacro:wheels_friction side="near_right"/-->
</robot>
