<?xml version="1.0" ?>
<!-- =================================================================================== -->
<!-- |    This document was autogenerated by xacro from agro2.urdf.xacro               | -->
<!-- |    EDITING THIS FILE BY HAND IS NOT RECOMMENDED                                 | -->
<!-- =================================================================================== -->
<robot name="robot_name">
  <!-- ************************ -->
  <!--  variables -->
  <!-- ************************ -->
  <!--<xacro:property name="wheel_radius" value="0.0615"/>
  <xacro:property name="base_width" value="0.316"/>
  <xacro:property name="wheel_distance" value="0.225"/>-->
  <link name="base_link">
    <visual>
      <origin rpy="0.0 0.0 0.0" xyz="0.0 0.0 0.0"/>
      <geometry>
        <box size="0.5 0.316 0.16"/>
      </geometry>
      <material name="">
        <color rgba="1.0 0.0 0.0 1.0"/>
        <texture filename=""/>
      </material>
    </visual>
  </link>
  <link name="front_left_wheel">
    <visual name="">
      <origin rpy="1.57 0.0 0.0" xyz="0.0 0.0 0.0"/>
      <geometry>
        <cylinder length="0.0615" radius="0.12"/>
      </geometry>
      <material name="">
        <color rgba="1.0 0.0 0.0 1.0"/>
        <texture filename=""/>
      </material>
    </visual>
  </link>
  <link name="front_right_wheel">
    <visual name="">
      <origin rpy="1.57 0.0 0.0" xyz="0.0 0.0 0.0"/>
      <geometry>
        <cylinder length="0.0615" radius="0.12"/>
      </geometry>
      <material name="">
        <color rgba="1.0 0.0 0.0 1.0"/>
        <texture filename=""/>
      </material>
    </visual>
  </link>
  <link name="near_left_wheel">
    <visual name="">
      <origin rpy="1.57 0.0 0.0" xyz="0.0 0.0 0.0"/>
      <geometry>
        <cylinder length="0.0615" radius="0.12"/>
      </geometry>
      <material name="">
        <color rgba="1.0 0.0 0.0 1.0"/>
        <texture filename=""/>
      </material>
    </visual>
  </link>
  <link name="near_right_wheel">
    <visual name="">
      <origin rpy="1.57 0.0 0.0" xyz="0.0 0.0 0.0"/>
      <geometry>
        <cylinder length="0.0615" radius="0.12"/>
      </geometry>
      <material name="">
        <color rgba="1.0 0.0 0.0 1.0"/>
        <texture filename=""/>
      </material>
    </visual>
  </link>
  <joint name="front_left_joint" type="continuous">
    <origin rpy="0.0 0.0 0.0" xyz="0.225 0.18875 0.0"/>
    <parent link="base_link"/>
    <child link="front_left_wheel"/>
    <axis xyz="0.0 0.1 0.0"/>
    <limit effort="0.0" lower="0.0" upper="0.0" velocity="0.0"/>
  </joint>
  <joint name="front_right_joint" type="continuous">
    <origin rpy="0.0 0.0 0.0" xyz="0.225 -0.18875 0.0"/>
    <parent link="base_link"/>
    <child link="front_right_wheel"/>
    <axis xyz="0.0 0.1 0.0"/>
    <limit effort="0.0" lower="0.0" upper="0.0" velocity="0.0"/>
  </joint>
  <joint name="near_left_joint" type="continuous">
    <origin rpy="0.0 0.0 0.0" xyz="-0.225 0.18875 0.0"/>
    <parent link="base_link"/>
    <child link="near_left_wheel"/>
    <axis xyz="0.0 0.1 0.0"/>
    <limit effort="0.0" lower="0.0" upper="0.0" velocity="0.0"/>
  </joint>
  <joint name="near_right_joint" type="continuous">
    <origin rpy="0.0 0.0 0.0" xyz="-0.225 -0.18875 0.0"/>
    <parent link="base_link"/>
    <child link="near_right_wheel"/>
    <axis xyz="0.0 0.1 0.0"/>
    <limit effort="0.0" lower="0.0" upper="0.0" velocity="0.0"/>
  </joint>

</robot>
