<?xml version="1.0"?>
<robot xmlns:xacro="http://www.ros.org/wiki/xacro" name="robot_name">
    

    <xacro:include filename="$(find agro_description)/urdf/xacro/inertial.xacro"/>
    <xacro:include filename="$(find agro_description)/urdf/xacro/properties.xacro"/>

    <xacro:macro name="base_camera">
     <link name="base_camera_link">
        <visual name="">
            <origin xyz="0.0 0.0 0.0" rpy="0.0 0.0 0.0"/>
            <!--geometry>
                <cylinder radius="0.12" length="0.0615"/>
            </geometry-->
            <geometry>
                <mesh filename="file://$(find agro_description)/mesh/rueda.stl" scale="0.001 0.001 0.001"/>
            </geometry>
            <material name="material_wheel">
                <color rgba="0.0 0.0 0.0 1.0"/>
            </material>

        </visual>
        <xacro:inertial_cylinder mass="${wheel_mass}" length="${wheel_length}" radius="${wheel_radius}">
            <origin xyz="0.0 0 0" rpy="0 0 0"/>
        </xacro:inertial_cylinder> 
        <collision>
            <origin xyz="0.0 0.0 0.0" rpy="0.0 0.0 0.0"/>
            <geometry>
                <cylinder radius="${wheel_radius}" length="${wheel_length}"/>
            </geometry>
        </collision>
     </link>
    </xacro:macro>

    <xacro:macro name="wheel_joint" params="prefix x y">
     <joint name="${prefix}_joint" type="continuous">
        <origin xyz="${x} ${y} 0.0" rpy="0.0 0.0 0.0"/>
        <parent link="base_link"/>
        <child link="${prefix}_wheel"/>
        <axis xyz="0.0 0.1 0.0"/>
        <limit lower="0.0" upper="0.0" effort="0.0" velocity="0.0"/>
     </joint>
    </xacro:macro>

</robot>