<?xml version="1.0"?>
<robot xmlns:xacro="http://www.ros.org/wiki/xacro" name="robot_name">
    

    <xacro:include filename="$(find agro_description)/urdf/xacro/inertial.xacro"/>
    <xacro:include filename="$(find agro_description)/urdf/xacro/properties.xacro"/>

    <xacro:macro name="wheel_link" params="prefix">
     <link name="${prefix}_wheel">

        <visual name="">
            <origin xyz="0.0 0.0 0.0" rpy="1.57 0.0 0.0"/>
            <geometry>
                <mesh filename="file://$(find agro_description)/mesh/rueda.stl" scale="0.001 0.001 0.001"/>
            </geometry>
            <material name="material_wheel">
                <color rgba="0.0 0.0 0.0 1.0"/>
            </material>
        </visual>

        <xacro:inertial_cylinder mass="${wheel_mass}" length="${wheel_length}" radius="${wheel_radius}">
            <origin xyz="0.0 0 0" rpy="1.57  0 0"/>
        </xacro:inertial_cylinder> 

        <collision>
            <origin xyz="0.0 0.0 0.0" rpy="1.57  0.0 0.0"/>
            <geometry>
                <cylinder radius="${wheel_radius}" length="${wheel_length}"/>
            </geometry>
        </collision>
     </link>
    </xacro:macro>

    <xacro:macro name="wheel_joint" params="prefix x y z">
     <joint name="${prefix}_joint" type="continuous">
        <origin xyz="${x} ${y} ${z}" rpy="0.0 0.0 0.0"/>
        <parent link="base_link"/>
        <child link="${prefix}_wheel"/>
        <axis xyz="0.0 1.0 0.0"/>
        <limit effort="1.5" velocity="30.0" />
        <dynamics damping="0.001" friction="0.001" />
     </joint>
    </xacro:macro>

</robot>